Workbook

Sheet Instellingen
A1: Kostenaannames
A2: Blauwe cellen pas je zelf aan op basis van de actuele tarievenkaart van je broker.
A4: Parameter | B4: Waarde | C4: Toelichting / bron
A5: Vaste transactiekosten per order (€) | B5: 5 | C5: €5 per order bij ABN AMRO buitenlandse aandelen (controleer tarievenkaart)
A6: Variabele transactiekosten (% van orderwaarde) | B6: 0.0005 | C6: 0,05% bij ABN AMRO buitenlandse aandelen
A7: Wisselkoersmarge per kant (% van orderwaarde) | B7: 0.002 | C7: Schatting voor EUR<>USD omrekening; 0 als je in EUR-aandelen handelt
A8: Servicekosten per jaar (% van portefeuille) | B8: 0.002 | C8: 0,20%/jaar volgens review; tarievenkaart is leidend
A9: Streefwinst per trade (%) | B9: 0.05 | C9: Jouw exit-doel: verkopen bij +5%
A12: Break-even: minimale koersstijging om quitte te spelen
A13: Bij een order van €1.000 betaal je 2x transactiekosten (koop + verkoop) plus marge. Dat is grofweg (2 × €5) + (2 × 0,05% × €1.000) = €11. Je moet dus ~1,1% stijgen voordat je winst maakt — en dat percentage is groter naarmate je order kleiner is.

Sheet Trades
A1: Transactielogboek
A2: Witte kolommen vul je in. Grijze (formules) rekenen automatisch het netto rendement uit na alle kosten.
A4: Ticker | B4: Naam | C4: Koopdatum | D4: Koop­koers (€) | E4: Aantal | F4: Orderwaarde koop (€) | G4: Koopkosten (€) | H4: Verkoop­datum | I4: Verkoop­koers (€) | J4: Orderwaarde verkoop (€) | K4: Verkoopkosten (€) | L4: Bruto W/V (€) | M4: Totale kosten (€) | N4: Netto W/V (€) | O4: Netto rendement % | P4: Status
A5: ASML | B5: ASML Holding | C5: 2026-06-10 | D5: 980 | E5: 5 | F5: =D5*E5 | G5: =Instellingen!$B$5+(Instellingen!$B$6+Instellingen!$B$7)*F5 | H5: 2026-06-24 | I5: 1031 | J5: =IF(I5="","",I5*E5) | K5: =IF(I5="","",Instellingen!$B$5+(Instellingen!$B$6+Instellingen!$B$7)*J5) | L5: =IF(I5="","",J5-F5) | M5: =IF(I5="",G5,G5+K5) | N5: =IF(I5="","",L5-M5) | O5: =IF(I5="","",N5/F5) | P5: =IF(I5="","Open",IF(N5>=0,"Winst","Verlies"))
A6: NVDA | B6: NVIDIA | C6: 2026-06-12 | D6: 118.5 | E6: 40 | F6: =D6*E6 | G6: =Instellingen!$B$5+(Instellingen!$B$6+Instellingen!$B$7)*F6 | J6: =IF(I6="","",I6*E6) | K6: =IF(I6="","",Instellingen!$B$5+(Instellingen!$B$6+Instellingen!$B$7)*J6) | L6: =IF(I6="","",J6-F6) | M6: =IF(I6="",G6,G6+K6) | N6: =IF(I6="","",L6-M6) | O6: =IF(I6="","",N6/F6) | P6: =IF(I6="","Open",IF(N6>=0,"Winst","Verlies"))
A7: SHELL | B7: Shell plc | C7: 2026-06-15 | D7: 31.2 | E7: 60 | F7: =D7*E7 | G7: =Instellingen!$B$5+(Instellingen!$B$6+Instellingen!$B$7)*F7 | H7: 2026-06-27 | I7: 32.05 | J7: =IF(I7="","",I7*E7) | K7: =IF(I7="","",Instellingen!$B$5+(Instellingen!$B$6+Instellingen!$B$7)*J7) | L7: =IF(I7="","",J7-F7) | M7: =IF(I7="",G7,G7+K7) | N7: =IF(I7="","",L7-M7) | O7: =IF(I7="","",N7/F7) | P7: =IF(I7="","Open",IF(N7>=0,"Winst","Verlies"))
F8: =IF(E8="","",D8*E8) | G8: =IF(F8="","",Instellingen!$B$5+(Instellingen!$B$6+Instellingen!$B$7)*F8) | J8: =IF(I8="","",I8*E8) | K8: =IF(I8="","",Instellingen!$B$5+(Instellingen!$B$6+Instellingen!$B$7)*J8) | L8: =IF(I8="","",J8-F8) | M8: =IF(F8="","",IF(I8="",G8,G8+K8)) | N8: =IF(I8="","",L8-M8) | O8: =IF(I8="","",N8/F8) | P8: =IF(D8="","",IF(I8="","Open",IF(N8>=0,"Winst","Verlies")))
F9: =IF(E9="","",D9*E9) | G9: =IF(F9="","",Instellingen!$B$5+(Instellingen!$B$6+Instellingen!$B$7)*F9) | J9: =IF(I9="","",I9*E9) | K9: =IF(I9="","",Instellingen!$B$5+(Instellingen!$B$6+Instellingen!$B$7)*J9) | L9: =IF(I9="","",J9-F9) | M9: =IF(F9="","",IF(I9="",G9,G9+K9)) | N9: =IF(I9="","",L9-M9) | O9: =IF(I9="","",N9/F9) | P9: =IF(D9="","",IF(I9="","Open",IF(N9>=0,"Winst","Verlies")))
F10: =IF(E10="","",D10*E10) | G10: =IF(F10="","",Instellingen!$B$5+(Instellingen!$B$6+Instellingen!$B$7)*F10) | J10: =IF(I10="","",I10*E10) | K10: =IF(I10="","",Instellingen!$B$5+(Instellingen!$B$6+Instellingen!$B$7)*J10) | L10: =IF(I10="","",J10-F10) | M10: =IF(F10="","",IF(I10="",G10,G10+K10)) | N10: =IF(I10="","",L10-M10) | O10: =IF(I10="","",N10/F10) | P10: =IF(D10="","",IF(I10="","Open",IF(N10>=0,"Winst","Verlies")))
F11: =IF(E11="","",D11*E11) | G11: =IF(F11="","",Instellingen!$B$5+(Instellingen!$B$6+Instellingen!$B$7)*F11) | J11: =IF(I11="","",I11*E11) | K11: =IF(I11="","",Instellingen!$B$5+(Instellingen!$B$6+Instellingen!$B$7)*J11) | L11: =IF(I11="","",J11-F11) | M11: =IF(F11="","",IF(I11="",G11,G11+K11)) | N11: =IF(I11="","",L11-M11) | O11: =IF(I11="","",N11/F11) | P11: =IF(D11="","",IF(I11="","Open",IF(N11>=0,"Winst","Verlies")))
F12: =IF(E12="","",D12*E12) | G12: =IF(F12="","",Instellingen!$B$5+(Instellingen!$B$6+Instellingen!$B$7)*F12) | J12: =IF(I12="","",I12*E12) | K12: =IF(I12="","",Instellingen!$B$5+(Instellingen!$B$6+Instellingen!$B$7)*J12) | L12: =IF(I12="","",J12-F12) | M12: =IF(F12="","",IF(I12="",G12,G12+K12)) | N12: =IF(I12="","",L12-M12) | O12: =IF(I12="","",N12/F12) | P12: =IF(D12="","",IF(I12="","Open",IF(N12>=0,"Winst","Verlies")))
F13: =IF(E13="","",D13*E13) | G13: =IF(F13="","",Instellingen!$B$5+(Instellingen!$B$6+Instellingen!$B$7)*F13) | J13: =IF(I13="","",I13*E13) | K13: =IF(I13="","",Instellingen!$B$5+(Instellingen!$B$6+Instellingen!$B$7)*J13) | L13: =IF(I13="","",J13-F13) | M13: =IF(F13="","",IF(I13="",G13,G13+K13)) | N13: =IF(I13="","",L13-M13) | O13: =IF(I13="","",N13/F13) | P13: =IF(D13="","",IF(I13="","Open",IF(N13>=0,"Winst","Verlies")))
F14: =IF(E14="","",D14*E14) | G14: =IF(F14="","",Instellingen!$B$5+(Instellingen!$B$6+Instellingen!$B$7)*F14) | J14: =IF(I14="","",I14*E14) | K14: =IF(I14="","",Instellingen!$B$5+(Instellingen!$B$6+Instellingen!$B$7)*J14) | L14: =IF(I14="","",J14-F14) | M14: =IF(F14="","",IF(I14="",G14,G14+K14)) | N14: =IF(I14="","",L14-M14) | O14: =IF(I14="","",N14/F14) | P14: =IF(D14="","",IF(I14="","Open",IF(N14>=0,"Winst","Verlies")))
F15: =IF(E15="","",D15*E15) | G15: =IF(F15="","",Instellingen!$B$5+(Instellingen!$B$6+Instellingen!$B$7)*F15) | J15: =IF(I15="","",I15*E15) | K15: =IF(I15="","",Instellingen!$B$5+(Instellingen!$B$6+Instellingen!$B$7)*J15) | L15: =IF(I15="","",J15-F15) | M15: =IF(F15="","",IF(I15="",G15,G15+K15)) | N15: =IF(I15="","",L15-M15) | O15: =IF(I15="","",N15/F15) | P15: =IF(D15="","",IF(I15="","Open",IF(N15>=0,"Winst","Verlies")))
F16: =IF(E16="","",D16*E16) | G16: =IF(F16="","",Instellingen!$B$5+(Instellingen!$B$6+Instellingen!$B$7)*F16) | J16: =IF(I16="","",I16*E16) | K16: =IF(I16="","",Instellingen!$B$5+(Instellingen!$B$6+Instellingen!$B$7)*J16) | L16: =IF(I16="","",J16-F16) | M16: =IF(F16="","",IF(I16="",G16,G16+K16)) | N16: =IF(I16="","",L16-M16) | O16: =IF(I16="","",N16/F16) | P16: =IF(D16="","",IF(I16="","Open",IF(N16>=0,"Winst","Verlies")))
F17: =IF(E17="","",D17*E17) | G17: =IF(F17="","",Instellingen!$B$5+(Instellingen!$B$6+Instellingen!$B$7)*F17) | J17: =IF(I17="","",I17*E17) | K17: =IF(I17="","",Instellingen!$B$5+(Instellingen!$B$6+Instellingen!$B$7)*J17) | L17: =IF(I17="","",J17-F17) | M17: =IF(F17="","",IF(I17="",G17,G17+K17)) | N17: =IF(I17="","",L17-M17) | O17: =IF(I17="","",N17/F17) | P17: =IF(D17="","",IF(I17="","Open",IF(N17>=0,"Winst","Verlies")))
F18: =IF(E18="","",D18*E18) | G18: =IF(F18="","",Instellingen!$B$5+(Instellingen!$B$6+Instellingen!$B$7)*F18) | J18: =IF(I18="","",I18*E18) | K18: =IF(I18="","",Instellingen!$B$5+(Instellingen!$B$6+Instellingen!$B$7)*J18) | L18: =IF(I18="","",J18-F18) | M18: =IF(F18="","",IF(I18="",G18,G18+K18)) | N18: =IF(I18="","",L18-M18) | O18: =IF(I18="","",N18/F18) | P18: =IF(D18="","",IF(I18="","Open",IF(N18>=0,"Winst","Verlies")))
F19: =IF(E19="","",D19*E19) | G19: =IF(F19="","",Instellingen!$B$5+(Instellingen!$B$6+Instellingen!$B$7)*F19) | J19: =IF(I19="","",I19*E19) | K19: =IF(I19="","",Instellingen!$B$5+(Instellingen!$B$6+Instellingen!$B$7)*J19) | L19: =IF(I19="","",J19-F19) | M19: =IF(F19="","",IF(I19="",G19,G19+K19)) | N19: =IF(I19="","",L19-M19) | O19: =IF(I19="","",N19/F19) | P19: =IF(D19="","",IF(I19="","Open",IF(N19>=0,"Winst","Verlies")))
... F22: =IF(E22="","",D22*E22) | G22: =IF(F22="","",Instellingen!$B$5+(Instellingen!$B$6+Instellingen!$B$7)*F22) | J22: =IF(I22="","",I22*E22) | K22: =IF(I22="","",Instellingen!$B$5+(Instellingen!$B$6+Instellingen!$B$7)*J22) | L22: =IF(I22="","",J22-F22) | M22: =IF(F22="","",IF(I22="",G22,G22+K22)) | N22: =IF(I22="","",L22-M22) | O22: =IF(I22="","",N22/F22) | P22: =IF(D22="","",IF(I22="","Open",IF(N22>=0,"Winst","Verlies")))
A24: TOTAAL | L24: =SUM(L5:L22) | M24: =SUM(M5:M22) | N24: =SUM(N5:N22)
A25: Win-rate | B25: =COUNTIF(P5:P22,"Winst")&" winst / "&COUNTIF(P5:P22,"Verlies")&" verlies"

Sheet Screener
A1: Dagelijkse screener — consistente stijgers (alle periodes)
A2: Kandidaten die over alle periodes tegelijk stijgen. Voorbeelddata; vervang met echte API-output.
A4: Datum gevonden | B4: Ticker | C4: Naam | D4: Koers (€) | E4: % 1 dag | F4: % 1 week | G4: % 1 mnd | H4: % 6 mnd | I4: % 1 jaar | J4: Voldoet aan filter | K4: Nieuwslink
A5: 2026-06-30 | B5: NVDA | C5: NVIDIA | D5: 118.5 | E5: 0.062 | F5: 0.081 | G5: 0.143 | H5: 0.31 | I5: 0.62 | J5: =IF(AND(E5>=0,F5>=0,G5>=0,H5>=0,I5>=0),"JA","nee") | K5: https://finnhub.io/
A6: 2026-06-30 | B6: ASML | C6: ASML Holding | D6: 1031 | E6: 0.051 | F6: 0.066 | G6: 0.092 | H6: 0.18 | I6: 0.27 | J6: =IF(AND(E6>=0,F6>=0,G6>=0,H6>=0,I6>=0),"JA","nee") | K6: https://finnhub.io/
A7: 2026-06-30 | B7: NOVO | C7: Novo Nordisk | D7: 92.4 | E7: 0.058 | F7: 0.072 | G7: 0.11 | H7: 0.04 | I7: -0.12 | J7: =IF(AND(E7>=0,F7>=0,G7>=0,H7>=0,I7>=0),"JA","nee") | K7: https://finnhub.io/
A8: 2026-06-30 | B8: SHELL | C8: Shell plc | D8: 32.05 | E8: 0.027 | F8: 0.041 | G8: 0.06 | H8: 0.09 | I8: 0.14 | J8: =IF(AND(E8>=0,F8>=0,G8>=0,H8>=0,I8>=0),"JA","nee") | K8: https://finnhub.io/
A9: 2026-06-30 | B9: ADYEN | C9: Adyen | D9: 1450 | E9: 0.071 | F9: 0.12 | G9: 0.19 | H9: 0.22 | I9: 0.41 | J9: =IF(AND(E9>=0,F9>=0,G9>=0,H9>=0,I9>=0),"JA","nee") | K9: https://finnhub.io/
A10: 2026-07-02 | B10: MRNA | C10: MRNA | D10: 72.5 | E10: 0.035270616 | F10: 0.19993383 | G10: 0.57403382 | H10: 1.3840842 | I10: 1.5270128 | J10: JA | K10: https://finnhub.io/api/news?id=ce17c9b20616cb8ef7fb4c956cf8e01b2a5840726dcd42cb21f3b2815fa23a4d
A11: 2026-07-02 | B11: PANW | C11: PANW | D11: 352.04001 | E11: 0.032314879 | F11: 0.23410221 | G11: 0.1715921 | H11: 0.88407812 | I11: 0.78175931 | J11: JA | K11: https://finnhub.io/api/news?id=ce17c9b20616cb8ef7fb4c956cf8e01b2a5840726dcd42cb21f3b2815fa23a4d
A12: 2026-07-02 | B12: VLO | C12: VLO | D12: 269.44 | E12: 0.034556903 | F12: 0.11141365 | G12: 0.067004585 | H12: 0.65216463 | I12: 1.0022744 | J12: JA | K12: https://finnhub.io/api/news?id=d71c87b4e3ae6fb243d4d6b47bfde62364599267d973b748c45a11855a68bd8d
A13: 2026-07-02 | B13: FTNT | C13: FTNT | D13: 158.98 | E13: 0.034891295 | F13: 0.094300641 | G13: 0.080467557 | H13: 0.97957914 | I13: 0.5520843 | J13: JA | K13: https://finnhub.io/api/news?id=3f2de5e2e03c7894f32a29aa93cebaad071cf8a927d60b440dfc30acd56f0e67
A14: 2026-07-02 | B14: ILMN | C14: ILMN | D14: 183.89 | E14: 0.045839717 | F14: 0.050259885 | G14: 0.11855235 | H14: 0.3852354 | I14: 0.87356084 | J14: JA | K14: https://finnhub.io/api/news?id=642dbaaa4dcdeb2324e5772ee4e261f7b01f70bc105a3db58ad95119f9c5dc79
A15: 2026-07-02 | B15: MPC | C15: MPC | D15: 264.87 | E15: 0.035983874 | F15: 0.074479741 | G15: 0.024008317 | H15: 0.63113984 | I15: 0.58901902 | J15: JA | K15: https://finnhub.io/api/news?id=9932bacd993c61d07cb86adcffc985bc1b5144f8e2f858a919eb685252fd5fb2
A16: 2026-07-02 | B16: OKTA | C16: OKTA | D16: 140.46001 | E16: 0.029388126 | F16: 0.18451682 | G16: 0.0047929999 | H16: 0.60654245 | I16: 0.42526639 | J16: JA | K16: https://finnhub.io/api/news?id=d9aae01b2aabcf5b23e2d9d799fc7073679e40d2e97dce70573f9a3040237524
A17: 2026-07-02 | B17: IBKR | C17: IBKR | D17: 93.25 | E17: 0.071346496 | F17: 0.0049574208 | G17: 0.051415012 | H17: 0.43761086 | I17: 0.66333803 | J17: JA | K17: https://finnhub.io/api/news?id=bcdeb32a91bc322e8f9d5505faecf809567ee18e2ab59d25261d806bc83e9fd2
A18: 2026-07-02 | B18: JNJ | C18: JNJ | D18: 253.98 | E18: 3.93531e-05 | F18: 0.053858903 | G18: 0.13632501 | H18: 0.24111261 | I18: 0.66961235 | J18: JA | K18: https://finnhub.io/api/news?id=c8e6dc50fd735c40b044c5e600be9279c4aaf39d3d94ab56517405101f9a9193
A19: 2026-07-02 | B19: WELL | C19: WELL | D19: 230.19 | E19: 0.014186902 | F19: 0.039561081 | G19: 0.16634577 | H19: 0.23295418 | I19: 0.54175343 | J19: JA | K19: https://finnhub.io/api/news?id=5fcd1dac75c2dc37080b1e974e293954b5b64bbbd74a3fc8f7eb9a5107a0396c
A20: 2026-07-02 | B20: MNST | C20: MNST | D20: 97.349998 | E20: 0.01279646 | F20: 0.027983122 | G20: 0.092592594 | H20: 0.25758938 | I20: 0.53210571 | J20: JA | K20: https://finnhub.io/api/news?id=72bf0ae826fe1cfbddf3f651ac1489245c4b00cc230f67a8d212075c3981c87a
A21: 2026-07-02 | B21: GE | C21: GE | D21: 374.94 | E21: 0.0032376085 | F21: 0.02476221 | G21: 0.15508317 | H21: 0.20429188 | I21: 0.51363158 | J21: JA | K21: https://finnhub.io/api/news?id=9fd240f15dd54783c692edf77484e4ff7fe4d876119ffc8c9460fb331faf3242
... A35: 2026-07-02 | B35: BAC | C35: BAC | D35: 58.360001 | E35: 0.024219043 | F35: 0.010912889 | G35: 0.13887066 | H35: 0.067200749 | I35: 0.2384483 | J35: JA | K35: https://finnhub.io/api/news?id=62e3320c8067d97fedf1de31317e2f7b7b8031e8a7b5e659cc418c7a4ff72c37
A36: 2026-07-02 | B36: LNG | C36: LNG | D36: 243.92 | E36: 0.020543089 | F36: 0.056571071 | G36: 0.070387892 | H36: 0.26722134 | I36: 0.043511692 | J36: JA
A37: 2026-07-02 | B37: PPG | C37: PPG | D37: 122.61 | E37: 0.010883005 | F37: 0.013473278 | G37: 0.094048371 | H37: 0.19713199 | I37: 0.081321755 | J37: JA | K37: https://finnhub.io/api/news?id=c951416ecc72a63cf30913b711c7a74304ee924ab29fcd42534cddc3814d3c39
A38: 2026-07-02 | B38: KO | C38: KO | D38: 81.290001 | E38: 0.00024614585 | F38: 0.0085608245 | G38: 0.040371704 | H38: 0.17564416 | I38: 0.16634848 | J38: JA | K38: https://finnhub.io/api/news?id=0dfc077852178496493e49b2401e7cc441fe47acd9b877d769b1356964c1bf60
A39: 2026-07-02 | B39: VRTX | C39: VRTX | D39: 498.01001 | E39: 0.0025768501 | F39: 0.048000835 | G39: 0.13597175 | H39: 0.097566934 | I39: 0.10140217 | J39: JA | K39: https://finnhub.io/api/news?id=52c78d706a9db26b953f778e31d58f1170246e7fa12bbe322dba66842da12231
A40: 2026-07-02 | B40: HEI | C40: HEI | D40: 359.70001 | E40: 0.010223037 | F40: 0.073162404 | G40: 0.079763916 | H40: 0.096577408 | I40: 0.11959973 | J40: JA | K40: https://finnhub.io/api/news?id=e19016de81486c66ffbabac7244a3c73617723904a2ab812e24b09546025899a
A41: 2026-07-02 | B41: JPM | C41: JPM | D41: 334.07001 | E41: 0.020590905 | F41: 0.0018593345 | G41: 0.12640779 | H41: 0.042898698 | I41: 0.17271103 | J41: JA | K41: https://finnhub.io/api/news?id=7845abcae42c6d8fdfb9581305ffd98552815efee432a7c5fb485089c18ab63b
A42: 2026-07-02 | B42: MET | C42: MET | D42: 87.199997 | E42: 0.030610995 | F42: 0.030732843 | G42: 0.065493657 | H42: 0.1092739 | I42: 0.10764365 | J42: JA | K42: https://finnhub.io/api/news?id=fad08d789d41b53a996fc9b4a509a59f0a955b30d7e433a39d22f2e2f310a179
A43: 2026-07-02 | B43: ED | C43: ED | D43: 110.95 | E43: 0.0028925219 | F43: 0.0020772735 | G43: 0.070945932 | H43: 0.12882465 | I43: 0.13749892 | J43: JA | K43: https://finnhub.io/api/news?id=c0cb7fff76359340c3cc313f962cb8d84dd1acab807b53770a183e3dcea94758
A44: 2026-07-02 | B44: YUM | C44: YUM | D44: 161.59 | E44: 0.010821942 | F44: 0.056005697 | G44: 0.095451172 | H44: 0.071948663 | I44: 0.095280318 | J44: JA | K44: https://finnhub.io/api/news?id=f8834127da5c310f76a0aea9d94163537ed905040f1b8a9bda7db45f375c1408
A45: 2026-07-02 | B45: LMT | C45: LMT | D45: 521.82001 | E45: 0.024261014 | F45: 0.061386364 | G45: 0.010300111 | H45: 0.081975796 | I45: 0.15013575 | J45: JA | K45: https://finnhub.io/api/news?id=398a6a71dc65a98b2e5e177bcbc62385eda75be538c33794adc9f6047bf96cda
A46: 2026-07-02 | B46: EA | C46: EA | D46: 205.45 | E46: 0.0019996278 | F46: 0.0045471966 | G46: 0.017079193 | H46: 0.0072856375 | I46: 0.29673706 | J46: JA | K46: https://finnhub.io/api/news?id=8f0208ea829fe2fcb50b52be94c337c6972843f388e3e41d7408dd7761552679
A47: 2026-07-02 | B47: UPS | C47: UPS | D47: 109.54 | E47: 0.018976753 | F47: 0.032033178 | G47: 0.0047698064 | H47: 0.13347894 | I47: 0.1206391 | J47: JA | K47: https://finnhub.io/api/news?id=8ca4c5c5e5f0ff12b9561c7fc957213d4e1f2c6a7b67680b72554cd658e242e6
A48: 2026-07-02 | B48: AFL | C48: AFL | D48: 118.49 | E48: 0.010575675 | F48: 0.0062844829 | G48: 0.056908369 | H48: 0.080653205 | I48: 0.14405074 | J48: JA | K48: https://finnhub.io/api/news?id=50eee2404279e4791e7827e06516f6fd1e5595c94ef8851a023fc0270413f207
... A78: 2026-07-02 | B78: BAC | C78: BAC | D78: 58.360001 | E78: 0.024219043 | F78: 0.010912889 | G78: 0.13887066 | H78: 0.067200749 | I78: 0.2384482 | J78: JA | K78: https://finnhub.io/api/news?id=ec8d9cbe2d5c3e5aebba8bfad5feed0311dcb23512d5bb4f91e41953ed344d93
A79: 2026-07-02 | B79: LNG | C79: LNG | D79: 243.92 | E79: 0.020543089 | F79: 0.056571071 | G79: 0.070387892 | H79: 0.26722134 | I79: 0.043511692 | J79: JA
A80: 2026-07-02 | B80: PPG | C80: PPG | D80: 122.61 | E80: 0.010883005 | F80: 0.013473278 | G80: 0.094048371 | H80: 0.19713199 | I80: 0.081321827 | J80: JA | K80: https://finnhub.io/api/news?id=c951416ecc72a63cf30913b711c7a74304ee924ab29fcd42534cddc3814d3c39
A81: 2026-07-02 | B81: KO | C81: KO | D81: 81.290001 | E81: 0.00024614585 | F81: 0.0085608245 | G81: 0.040371704 | H81: 0.17564429 | I81: 0.16634861 | J81: JA | K81: https://finnhub.io/api/news?id=4dfb99c2729f8a478c339938646829df6d4a3a90d9c44a7de157031b571ec336
A82: 2026-07-02 | B82: VRTX | C82: VRTX | D82: 498.01001 | E82: 0.0025768501 | F82: 0.048000835 | G82: 0.13597175 | H82: 0.097566934 | I82: 0.10140217 | J82: JA | K82: https://finnhub.io/api/news?id=52c78d706a9db26b953f778e31d58f1170246e7fa12bbe322dba66842da12231
A83: 2026-07-02 | B83: HEI | C83: HEI | D83: 359.70001 | E83: 0.010223037 | F83: 0.073162404 | G83: 0.079763916 | H83: 0.096577408 | I83: 0.11959973 | J83: JA | K83: https://finnhub.io/api/news?id=e19016de81486c66ffbabac7244a3c73617723904a2ab812e24b09546025899a
...
